Workbook

Sheet 命格祈祷基础
A1: ID | B1: 雕像名称 | C1: 神石ID | D1: 祈祷分组 | E1: 金币消耗
A2: 1 | B2: Hoàng thú hồn | C2: 100059 | D2: 1001 | E2: 100000
A3: 2 | B3: Huyền thú hồn | C3: 100059 | D3: 2001 | E3: 100000
A4: 3 | B4: Địa thú hồn | C4: 100059 | D4: 3001 | E4: 100000
A5: 4 | B5: Thiên thú hồn | C5: 100059 | D5: 4001 | E5: 100000

Sheet 命格雕像变更
A1: ID | B1: 初始雕像 | C1: 目标雕像 | D1: 权重
A2: 1 | B2: 1 | C2: 1 | D2: 5000
A3: 2 | B3: 1 | C3: 2 | D3: 5000
A4: 3 | B4: 1 | C4: 3 | D4: 0
A5: 4 | B5: 1 | C5: 4 | D5: 0
A6: 5 | B6: 2 | C6: 1 | D6: 7000
A7: 6 | B7: 2 | C7: 2 | D7: 0
A8: 7 | B8: 2 | C8: 3 | D8: 3000
A9: 8 | B9: 2 | C9: 4 | D9: 0
A10: 9 | B10: 3 | C10: 1 | D10: 8000
A11: 10 | B11: 3 | C11: 2 | D11: 0
A12: 11 | B12: 3 | C12: 3 | D12: 0
A13: 12 | B13: 3 | C13: 4 | D13: 2000
... A17: 16 | B17: 4 | C17: 4 | D17: 0

Sheet 命格祈祷奖励
A1: ID | B1: 分组 | C1: *权重 | D1: 展示权重 | E1: 奖励 | F1: *全服记录 | G1: 杂物 | H1: 出售金币 | I1: *名称 | J1: *品级 | K1: 排序
A2: 1 | B2: 1 | C2: 1250 | D2: 1250 | E2: 3:100053:1 | G2: 1 | H2: 20000 | I2: 黄级杂物 | J2: 0 | K2: 1
A3: 2 | B3: 1 | C3: 1250 | D3: 1250 | E3: 3:100054:1 | G3: 1 | H3: 40000 | I3: 玄级杂物 | J3: 0 | K3: 2
A4: 3 | B4: 1 | C4: 1250 | D4: 1250 | E4: 3:100055:1 | G4: 1 | H4: 60000 | I4: 地级杂物 | J4: 0 | K4: 3
A5: 4 | B5: 1 | C5: 1250 | D5: 1250 | E5: 3:100056:1 | G5: 1 | H5: 80000 | I5: 天级杂物 | J5: 0 | K5: 4
A6: 5 | B6: 1 | C6: 100 | D6: 100 | E6: 6:10001:1 | I6: 子鼠 | J6: 1 | K6: 14
A7: 6 | B7: 1 | C7: 100 | D7: 100 | E7: 6:10011:1 | I7: 丑牛 | J7: 1 | K7: 15
A8: 7 | B8: 1 | C8: 100 | D8: 100 | E8: 6:10021:1 | I8: 寅虎 | J8: 1 | K8: 16
A9: 8 | B9: 1 | C9: 100 | D9: 100 | E9: 6:10031:1 | I9: 卯兔 | J9: 1 | K9: 17
A10: 9 | B10: 1 | C10: 1500 | D10: 1500 | E10: 6:30001:5 | I10: 兽魂经验(小) | J10: 2 | K10: 5
A11: 10 | B11: 1 | C11: 1000 | D11: 1000 | E11: 6:30001:10 | I11: 兽魂经验(小) | J11: 2 | K11: 6
A12: 11 | B12: 1 | C12: 500 | D12: 500 | E12: 6:30001:15 | I12: 兽魂经验(小) | J12: 2 | K12: 7
A13: 12 | B13: 1 | C13: 500 | D13: 500 | E13: 6:30001:20 | I13: 兽魂经验(小) | J13: 2 | K13: 8
A14: 13 | B14: 1 | C14: 100 | D14: 100 | E14: 3:100031:10 | I14: 洗练石 | J14: 0 | K14: 12
A15: 14 | B15: 1 | C15: 200 | D15: 200 | E15: 3:100031:5 | I15: 洗练石 | J15: 0 | K15: 11
A16: 15 | B16: 1 | C16: 300 | D16: 300 | E16: 3:100031:3 | I16: 洗练石 | J16: 0 | K16: 10
A17: 16 | B17: 1 | C17: 400 | D17: 400 | E17: 3:100031:1 | I17: 洗练石 | J17: 0 | K17: 9
A18: 17 | B18: 1 | C18: 100 | D18: 100 | E18: 3:100036:1 | I18: 兽魂碎片 | J18: 2 | K18: 13
A19: 18 | B19: 2 | C19: 1000 | D19: 1000 | E19: 3:100053:1 | G19: 1 | H19: 20000 | I19: 黄级杂物 | J19: 0 | K19: 1
A20: 19 | B20: 2 | C20: 1000 | D20: 1000 | E20: 3:100054:1 | G20: 1 | H20: 40000 | I20: 玄级杂物 | J20: 0 | K20: 2
A21: 20 | B21: 2 | C21: 1000 | D21: 1000 | E21: 3:100055:1 | G21: 1 | H21: 60000 | I21: 地级杂物 | J21: 0 | K21: 3
A22: 21 | B22: 2 | C22: 1000 | D22: 1000 | E22: 3:100056:1 | G22: 1 | H22: 80000 | I22: 天级杂物 | J22: 0 | K22: 4
A23: 22 | B23: 2 | C23: 150 | D23: 150 | E23: 6:10001:1 | I23: 子鼠 | J23: 1 | K23: 14
A24: 23 | B24: 2 | C24: 150 | D24: 150 | E24: 6:10011:1 | I24: 丑牛 | J24: 1 | K24: 15
A25: 24 | B25: 2 | C25: 150 | D25: 150 | E25: 6:10021:1 | I25: 寅虎 | J25: 1 | K25: 16
A26: 25 | B26: 2 | C26: 150 | D26: 150 | E26: 6:10031:1 | I26: 卯兔 | J26: 1 | K26: 17
A27: 26 | B27: 2 | C27: 100 | D27: 50 | E27: 6:10002:1 | F27: 1 | I27: 子鼠 | J27: 2 | K27: 18
A28: 27 | B28: 2 | C28: 100 | D28: 50 | E28: 6:10012:1 | F28: 1 | I28: 丑牛 | J28: 2 | K28: 19
A29: 28 | B29: 2 | C29: 100 | D29: 50 | E29: 6:10022:1 | F29: 1 | I29: 寅虎 | J29: 2 | K29: 20
A30: 29 | B30: 2 | C30: 20 | D30: 50 | E30: 6:10032:1 | F30: 1 | I30: 卯兔 | J30: 2 | K30: 21
A31: 30 | B31: 2 | C31: 20 | D31: 50 | E31: 6:10042:1 | F31: 1 | I31: 辰龙 | J31: 2 | K31: 22
A32: 31 | B32: 2 | C32: 20 | D32: 50 | E32: 6:10052:1 | F32: 1 | I32: 巳蛇 | J32: 2 | K32: 23
A33: 32 | B33: 2 | C33: 20 | D33: 50 | E33: 6:10072:1 | F33: 1 | I33: 未羊 | J33: 2 | K33: 24
A34: 33 | B34: 2 | C34: 20 | D34: 50 | E34: 6:10092:1 | F34: 1 | I34: 酉鸡 | J34: 2 | K34: 25
A35: 34 | B35: 2 | C35: 1400 | D35: 1400 | E35: 6:30001:5 | I35: 兽魂经验(小) | J35: 2 | K35: 5
A36: 35 | B36: 2 | C36: 1000 | D36: 1000 | E36: 6:30001:10 | I36: 兽魂经验(小) | J36: 2 | K36: 6
A37: 36 | B37: 2 | C37: 450 | D37: 450 | E37: 6:30001:15 | I37: 兽魂经验(小) | J37: 2 | K37: 7
A38: 37 | B38: 2 | C38: 450 | D38: 450 | E38: 6:30001:20 | I38: 兽魂经验(小) | J38: 2 | K38: 8
A39: 38 | B39: 2 | C39: 150 | D39: 150 | E39: 3:100031:10 | I39: 洗练石 | J39: 0 | K39: 12
A40: 39 | B40: 2 | C40: 300 | D40: 300 | E40: 3:100031:5 | I40: 洗练石 | J40: 0 | K40: 11
...

Sheet 命格祈祷作弊
A1: ID | B1: 雕像ID | C1: 次数 | D1: 分组
A2: 1 | B2: 1 | C2: 1 | D2: 8001

Sheet Sheet1
A1: 100053 | B1: 100000 | C1: =B1*0.5 -> 50000 | D1: 50000 | E1: 100000 | F1: 250000 | H1: 100053:1 | K1: 3:100053:1 | M1: =FIND(":",K1,1) -> 2 | N1: =RIGHT(K1,LEN(K1)-M1) -> 100053:1 | O1: =FIND(":",N1,1) -> 7 | P1: =LEFT(N1,O1-1) -> 100053 | Q1: 100053 | R1: =VLOOKUP(Q1,[1]命格基础!$A:$B,2,0) -> #N/A | S1: =VLOOKUP(Q1,[1]命格基础!$A:$C,3,0) -> #N/A
A2: 100054 | B2: 120000 | C2: =B2*0.5 -> 60000 | D2: 60000 | E2: 120000 | F2: 300000 | H2: 100054:1 | K2: 3:100054:1 | M2: =FIND(":",K2,1) -> 2 | N2: =RIGHT(K2,LEN(K2)-M2) -> 100054:1 | O2: =FIND(":",N2,1) -> 7 | P2: =LEFT(N2,O2-1) -> 100054 | Q2: 100054 | R2: =VLOOKUP(Q2,[1]命格基础!$A:$B,2,0) -> #N/A | S2: =VLOOKUP(Q2,[1]命格基础!$A:$C,3,0) -> #N/A
A3: 100055 | B3: 150000 | C3: =B3*0.5 -> 75000 | D3: 75000 | E3: 150000 | F3: 375000 | H3: 10001:1 | K3: 6:10001:1 | M3: =FIND(":",K3,1) -> 2 | N3: =RIGHT(K3,LEN(K3)-M3) -> 10001:1 | O3: =FIND(":",N3,1) -> 6 | P3: =LEFT(N3,O3-1) -> 10001 | Q3: 10001 | R3: =VLOOKUP(Q3,[1]命格基础!$A$1:$B$71,2,0) -> 子鼠 | S3: =VLOOKUP(Q3,[1]命格基础!$A:$C,3,0) -> 1
A4: 100056 | B4: 200000 | C4: =B4*0.5 -> 100000 | D4: 100000 | E4: 200000 | F4: 500000 | H4: 10011:1 | K4: 6:10011:1 | M4: =FIND(":",K4,1) -> 2 | N4: =RIGHT(K4,LEN(K4)-M4) -> 10011:1 | O4: =FIND(":",N4,1) -> 6 | P4: =LEFT(N4,O4-1) -> 10011 | Q4: 10011 | R4: =VLOOKUP(Q4,[1]命格基础!$A:$B,2,0) -> 丑牛 | S4: =VLOOKUP(Q4,[1]命格基础!$A:$C,3,0) -> 1
H5: 10021:1 | K5: 6:10021:1 | M5: =FIND(":",K5,1) -> 2 | N5: =RIGHT(K5,LEN(K5)-M5) -> 10021:1 | O5: =FIND(":",N5,1) -> 6 | P5: =LEFT(N5,O5-1) -> 10021 | Q5: 10021 | R5: =VLOOKUP(Q5,[1]命格基础!$A:$B,2,0) -> 寅虎 | S5: =VLOOKUP(Q5,[1]命格基础!$A:$C,3,0) -> 1
H6: 10031:1 | K6: 6:10031:1 | M6: =FIND(":",K6,1) -> 2 | N6: =RIGHT(K6,LEN(K6)-M6) -> 10031:1 | O6: =FIND(":",N6,1) -> 6 | P6: =LEFT(N6,O6-1) -> 10031 | Q6: 10031 | R6: =VLOOKUP(Q6,[1]命格基础!$A:$B,2,0) -> 卯兔 | S6: =VLOOKUP(Q6,[1]命格基础!$A:$C,3,0) -> 1
H7: 10041:1 | K7: 6:10041:1 | M7: =FIND(":",K7,1) -> 2 | N7: =RIGHT(K7,LEN(K7)-M7) -> 10041:1 | O7: =FIND(":",N7,1) -> 6 | P7: =LEFT(N7,O7-1) -> 10041 | Q7: 10041 | R7: =VLOOKUP(Q7,[1]命格基础!$A:$B,2,0) -> 辰龙 | S7: =VLOOKUP(Q7,[1]命格基础!$A:$C,3,0) -> 1
H8: 10051:1 | K8: 6:10051:1 | M8: =FIND(":",K8,1) -> 2 | N8: =RIGHT(K8,LEN(K8)-M8) -> 10051:1 | O8: =FIND(":",N8,1) -> 6 | P8: =LEFT(N8,O8-1) -> 10051 | Q8: 10051 | R8: =VLOOKUP(Q8,[1]命格基础!$A:$B,2,0) -> 巳蛇 | S8: =VLOOKUP(Q8,[1]命格基础!$A:$C,3,0) -> 1
H9: 10061:1 | K9: 6:10061:1 | M9: =FIND(":",K9,1) -> 2 | N9: =RIGHT(K9,LEN(K9)-M9) -> 10061:1 | O9: =FIND(":",N9,1) -> 6 | P9: =LEFT(N9,O9-1) -> 10061 | Q9: 10061 | R9: =VLOOKUP(Q9,[1]命格基础!$A:$B,2,0) -> 午马 | S9: =VLOOKUP(Q9,[1]命格基础!$A:$C,3,0) -> 1
H10: 10071:1 | K10: 6:10071:1 | M10: =FIND(":",K10,1) -> 2 | N10: =RIGHT(K10,LEN(K10)-M10) -> 10071:1 | O10: =FIND(":",N10,1) -> 6 | P10: =LEFT(N10,O10-1) -> 10071 | Q10: 10071 | R10: =VLOOKUP(Q10,[1]命格基础!$A:$B,2,0) -> 未羊 | S10: =VLOOKUP(Q10,[1]命格基础!$A:$C,3,0) -> 1
H11: 10081:1 | K11: 6:10081:1 | M11: =FIND(":",K11,1) -> 2 | N11: =RIGHT(K11,LEN(K11)-M11) -> 10081:1 | O11: =FIND(":",N11,1) -> 6 | P11: =LEFT(N11,O11-1) -> 10081 | Q11: 10081 | R11: =VLOOKUP(Q11,[1]命格基础!$A:$B,2,0) -> 申猴 | S11: =VLOOKUP(Q11,[1]命格基础!$A:$C,3,0) -> 1
H12: 10091:1 | K12: 6:10091:1 | M12: =FIND(":",K12,1) -> 2 | N12: =RIGHT(K12,LEN(K12)-M12) -> 10091:1 | O12: =FIND(":",N12,1) -> 6 | P12: =LEFT(N12,O12-1) -> 10091 | Q12: 10091 | R12: =VLOOKUP(Q12,[1]命格基础!$A:$B,2,0) -> 酉鸡 | S12: =VLOOKUP(Q12,[1]命格基础!$A:$C,3,0) -> 1
H13: 10101:1 | K13: 6:10101:1 | M13: =FIND(":",K13,1) -> 2 | N13: =RIGHT(K13,LEN(K13)-M13) -> 10101:1 | O13: =FIND(":",N13,1) -> 6 | P13: =LEFT(N13,O13-1) -> 10101 | Q13: 10101 | R13: =VLOOKUP(Q13,[1]命格基础!$A:$B,2,0) -> 戌狗 | S13: =VLOOKUP(Q13,[1]命格基础!$A:$C,3,0) -> 1
H14: 10111:1 | K14: 6:10111:1 | M14: =FIND(":",K14,1) -> 2 | N14: =RIGHT(K14,LEN(K14)-M14) -> 10111:1 | O14: =FIND(":",N14,1) -> 6 | P14: =LEFT(N14,O14-1) -> 10111 | Q14: 10111 | R14: =VLOOKUP(Q14,[1]命格基础!$A:$B,2,0) -> 亥猪 | S14: =VLOOKUP(Q14,[1]命格基础!$A:$C,3,0) -> 1
H15: 10002:1 | K15: 6:10002:1 | M15: =FIND(":",K15,1) -> 2 | N15: =RIGHT(K15,LEN(K15)-M15) -> 10002:1 | O15: =FIND(":",N15,1) -> 6 | P15: =LEFT(N15,O15-1) -> 10002 | Q15: 10002 | R15: =VLOOKUP(Q15,[1]命格基础!$A:$B,2,0) -> 子鼠 | S15: =VLOOKUP(Q15,[1]命格基础!$A:$C,3,0) -> 2
H16: 10012:1 | K16: 6:10012:1 | M16: =FIND(":",K16,1) -> 2 | N16: =RIGHT(K16,LEN(K16)-M16) -> 10012:1 | O16: =FIND(":",N16,1) -> 6 | P16: =LEFT(N16,O16-1) -> 10012 | Q16: 10012 | R16: =VLOOKUP(Q16,[1]命格基础!$A:$B,2,0) -> 丑牛 | S16: =VLOOKUP(Q16,[1]命格基础!$A:$C,3,0) -> 2
... H271: 10001:1 | K271: 6:10001:1 | M271: =FIND(":",K271,1) -> 2 | N271: =RIGHT(K271,LEN(K271)-M271) -> 10001:1 | O271: =FIND(":",N271,1) -> 6 | P271: =LEFT(N271,O271-1) -> 10001 | Q271: 10001 | R271: =VLOOKUP(Q271,[1]命格基础!$A:$B,2,0) -> 子鼠 | S271: =VLOOKUP(Q271,[1]命格基础!$A:$C,3,0) -> 1
